Workbook

Sheet kriteria & sub
B4: Karbohidrat | D4: Lemak | F4: Protein | H4: Serat | J4: Natrium
B5: W=2 | D5: W=3 | F5: W=4 | H5: W=4 | J5: W=5
B6: W=10% | D6: W=15% | F6: W=20% | H6: W=25% | J6: W=30%
B7: Rentang Penilaian/100gr | C7: Rangking | D7: Rentang Penilaian/100gr | E7: Rangking | F7: Rentang Penilaian/100gr | G7: Rangking | H7: Rentang Penilaian/100gr | I7: Rangking | J7: Rentang Penilaian/100gr | K7: Rangking
B8: 0-1 | C8: 1 | D8: 0-1 | E8: 1 | F8: 0-1 | G8: 1 | H8: 0-1 | I8: 1 | J8: >500 | K8: 1
B9: 1 - 25 | C9: 2 | D9: 1 - 25 | E9: 2 | F9: 1 - 25 | G9: 2 | H9: 1 - 3 | I9: 2 | J9: 350-500 | K9: 2
B10: 25-30 | C10: 3 | D10: 25-30 | E10: 3 | F10: 25-30 | G10: 3 | H10: 3 - 5 | I10: 3 | J10: 200-350 | K10: 3
B11: 55-75 | C11: 4 | D11: 55-75 | E11: 4 | F11: 55-75 | G11: 4 | H11: 5 - 7 | I11: 4 | J11: 100-200 | K11: 4
B12: 75-100 | C12: 5 | D12: 75-100 | E12: 5 | F12: 75-100 | G12: 5 | H12: >7 | I12: 5 | J12: 0-100 | K12: 5
B40: ALT | E40: C1 | G40: C2 | I40: C3 | J40: C4 | K40: C5
B41: 1 | E41: 2 | G41: 3 | I41: 4 | J41: 5 | K41: 1
B42: 2 | E42: 3 | G42: 4 | I42: 5 | J42: 1 | K42: 2
B43: 3 | E43: 4 | G43: 5 | I43: 1 | J43: 2 | K43: 3
B44: 4 | E44: 5 | G44: 1 | I44: 2 | J44: 3 | K44: 4
B45: 5 | E45: 1 | G45: 2 | I45: 3 | J45: 4 | K45: 5

Sheet data clean
B5: Nama Bahan Makanan | C5: Protein | D5: Lemak | E5: Karbohidrat | F5: Serat | G5: Natrium (Na) ⇲
C6: (g) | D6: (g) | E6: (g) | F6: (g) | G6: (mg)
B7: Nasi | C7: 3 | D7: 0.3 | E7: 39.8 | F7: 0.2 | G7: 1
B8: Biskuit | C8: 6.9 | D8: 14.4 | E8: 75.1 | F8: 2.1 | G8: 241
B9: Bubur tinotuan (Manado) | C9: 2.3 | D9: 0.2 | E9: 15.6 | F9: 8.2 | G9: 486
B10: Mie bakso | C10: 5.3 | D10: 3 | E10: 16.4 | F10: 0.1 | G10: 760
B11: Beras giling, mentah | C11: 8.4 | D11: 1.7 | E11: 77.1 | F11: 0.2 | G11: 27
B12: Beras jagung kuning, kering, mentah | C12: 5.5 | D12: 0.1 | E12: 82.7 | F12: 10 | G12: 1
B13: Batatas kelapa, ubi, bakar | C13: 1.4 | D13: 1.1 | E13: 23.4 | F13: 4.5 | G13: 12
B14: Batatas kelapa, ubi, kukus | C14: 1.2 | D14: 0.3 | E14: 21 | F14: 4.1 | G14: 10
B15: Batatas tali, ubi, rebus | C15: 2.4 | D15: 0.4 | E15: 42.2 | F15: 9.2 | G15: 20
B16: Belitung, talas, kukus | C16: 1.2 | D16: 0.4 | E16: 34.2 | F16: 1 | G16: 7
B17: Ketela pohon/singkong kukus | C17: 1.2 | D17: 0.3 | E17: 36.4 | F17: 1.3 | G17: 2
B18: Ubi jalar, kuning, kukus | C18: 0.7 | D18: 0.3 | E18: 23.8 | F18: 1 | G18: 3
... B58: Bayam spinacia, beku, cincang atau daun, dimasak, direbus, tiriskan, tanpa garam | C58: 4.01 | D58: 0.87 | E58: 4.8 | F58: 3.7 | G58: 97

Sheet data raw
B5: Nama Bahan Makanan | C5: Air | D5: Energi | E5: Protein | F5: Lemak | G5: Karbohidrat | H5: Serat | I5: Abu | J5: Kalsium (Ca | K5: Fosfor (P) ⇲ | L5: Besi (Fe) ⇲ | M5: Natrium (Na) ⇲
C6: (g) | D6: (Kal) | E6: (g) | F6: (g) | G6: (g) | H6: (g) | I6: (g) | J6: (mg) | K6: (mg) | L6: (mg) | M6: (mg)
B7: Nasi | C7: 56.7 | D7: 180 | E7: 3 | F7: 0.3 | G7: 39.8 | H7: 0.2 | I7: 0.2 | J7: 25 | K7: 27 | L7: 0.4 | M7: 1
B8: Biskuit | C8: 2.2 | D8: 458 | E8: 6.9 | F8: 14.4 | G8: 75.1 | H8: 2.1 | I8: 1.4 | J8: 62 | K8: 87 | L8: 2.7 | M8: 241
B9: Bubur tinotuan (Manado) | C9: 80.9 | D9: 156 | E9: 2.3 | F9: 0.2 | G9: 15.6 | H9: 8.2 | I9: 1 | J9: 41 | K9: 20 | L9: 0.4 | M9: 486
B10: Mie bakso | C10: 74.5 | D10: 114 | E10: 5.3 | F10: 3 | G10: 16.4 | H10: 0.1 | I10: 0.8 | J10: 286 | K10: 53 | L10: 1.9 | M10: 760
B11: Beras giling, mentah | C11: 12 | D11: 357 | E11: 8.4 | F11: 1.7 | G11: 77.1 | H11: 0.2 | I11: 0.8 | J11: 147 | K11: 81 | L11: 1.8 | M11: 27
B12: Beras jagung kuning, kering, mentah | C12: 10.8 | D12: 358 | E12: 5.5 | F12: 0.1 | G12: 82.7 | H12: 10 | I12: 0.9 | J12: 20 | K12: 90 | L12: 1.4 | M12: 1
B13: Batatas kelapa, ubi, bakar | C13: 73.2 | D13: 110 | E13: 1.4 | F13: 1.1 | G13: 23.4 | H13: 4.5 | I13: 0.7 | J13: 1 | K13: 46 | L13: 0.2 | M13: 12
B14: Batatas kelapa, ubi, kukus | C14: 75.7 | D14: 92 | E14: 1.2 | F14: 0.3 | G14: 21 | H14: 4.1 | I14: 1.8 | J14: - | K14: 42 | L14: 0.2 | M14: 10
B15: Batatas tali, ubi, rebus | C15: 53.2 | D15: 182 | E15: 2.4 | F15: 0.4 | G15: 42.2 | H15: 9.2 | I15: 1.8 | J15: 1 | K15: 80 | L15: 0.3 | M15: 20
B16: Belitung, talas, kukus | C16: 63.1 | D16: 145 | E16: 1.2 | F16: 0.4 | G16: 34.2 | H16: 1 | I16: 1.1 | J16: 21 | K16: 48 | L16: 0.9 | M16: 7
B17: Ketela pohon/singkong kukus | C17: 61.5 | D17: 153 | E17: 1.2 | F17: 0.3 | G17: 36.4 | H17: 1.3 | I17: 0.6 | J17: 56 | K17: 22 | L17: 0.4 | M17: 2
B18: Ubi jalar, kuning, kukus | C18: 74.2 | D18: 100 | E18: 0.7 | F18: 0.3 | G18: 23.8 | H18: 1 | I18: 1 | J18: 44 | K18: 46 | L18: 0.4 | M18: 3
B19: Ubi jalar tinta/ kemayung kukus | C19: 58.5 | D19: 165 | E19: 0.9 | F19: 0.2 | G19: 39.8 | H19: 1.1 | I19: 0.6 | J19: 20 | K19: 23 | L19: 0.8 | M19: 1
B20: Ubi jalar merah, segar | C20: 61.9 | D20: 151 | E20: 1.6 | F20: 0.3 | G20: 35.4 | H20: 0.7 | I20: 0.6 | J20: 29 | K20: 74 | L20: 0.7 | M20: 92
B21: Ubi jalar putih, segar | C21: 77.8 | D21: 88 | E21: 0.4 | F21: 0.4 | G21: 20.6 | H21: 4 | I21: 0.8 | J21: 30 | K21: 10 | L21: 0.5 | M21: 2
B22: Keripik kentang | C22: 7.8 | D22: 448 | E22: 2.7 | F22: 18.8 | G22: 67.1 | H22: 3.8 | I22: 3.6 | J22: 25 | K22: 130 | L22: 1.2 | M22: 712
B23: Keripik ubi | C23: 6 | D23: 486 | E23: 0.2 | F23: 23.9 | G23: 67.6 | H23: 14.3 | I23: 2.3 | J23: 68 | K23: 92 | L23: 0.9 | M23: 52
B24: Kerupuk cumi goreng | C24: 3.4 | D24: 444 | E24: 6.9 | F24: 14.6 | G24: 71.3 | H24: 5 | I24: 3.8 | J24: 47 | K24: 375 | L24: 1.8 | M24: 837
B25: Kerupuk udang goreng | C25: 4.4 | D25: 477 | E25: 4.7 | F25: 20.5 | G25: 68.5 | H25: 5 | I25: 1.9 | J25: 24 | K25: 188 | L25: 0.9 | M25: 449
B26: Kue putu singkong | C26: 44.2 | D26: 217 | E26: 1.2 | F26: 0.5 | G26: 53.2 | H26: 2.4 | I26: 0.9 | J26: 48 | K26: 68 | L26: 1.5 | M26: 3
... B33: Kacang mete/biji jambu monyet, goreng | C33: 1 | D33: 629 | E33: 20.4 | F33: 56.3 | G33: 19.8 | H33: 1.1 | I33: 2.5 | J33: 502 | K33: 493 | L33: 8 | M33: 13
B34: Kacang tanah rebus dg kulit | C34: 40.2 | D34: 360 | E34: 13.5 | F34: 31.2 | G34: 12.8 | H34: - | I34: 2.3 | J34: 42 | K34: 177 | L34: 1.4 | M34: 32
B35: Dodol banjarmasin | C35: 17.3 | D35: 368 | E35: 2.6 | F35: 8.6 | G35: 70 | H35: 0.5 | I35: 1.5 | J35: 51 | K35: 180 | L35: 3.3 | M35: 48
B36: Emping komak | C36: 14.2 | D36: 355 | E36: 17.8 | F36: 4.6 | G36: 60.7 | H36: - | I36: 2.7 | J36: 87 | K36: 304 | L36: 4.3 | M36: 24
B37: Keju kacang tanah (peanut butter) | C37: 3 | D37: 590 | E37: 27 | F37: 49 | G37: 20.9 | H37: 1.6 | I37: 0.1 | J37: 60 | K37: 360 | L37: 2 | M37: 355
B38: Kwaci | C38: 9.9 | D38: 515 | E38: 30.6 | F38: 42.1 | G38: 13.8 | H38: 13.6 | I38: 3.7 | J38: 54 | K38: 312 | L38: 6.2 | M38: 124
B39: Moon tahu | C39: 79.9 | D39: 128 | E39: 8 | F39: 10 | G39: 1.3 | H39: 0.2 | I39: 0.8 | J39: 205 | K39: 92 | L39: 2.5 | M39: 393
B40: Sayur lebui | C40: 83.9 | D40: 64 | E40: 2.1 | F40: 0.6 | G40: 12.5 | H40: 5.7 | I40: 0.9 | J40: 21 | K40: 2 | L40: 1 | M40: 124
B41: Susu kedelai | C41: 87 | D41: 41 | E41: 3.5 | F41: 2.5 | G41: 5 | H41: 0.2 | I41: 2 | J41: 50 | K41: 45 | L41: 0.7 | M41: 128
B42: Tahu goreng | C42: 77.3 | D42: 115 | E42: 9.7 | F42: 8.5 | G42: 2.5 | H42: 0.1 | I42: 2 | J42: 229 | K42: 200 | L42: 4.1 | M42: 7
B43: Tahu telur | C43: 41.8 | D43: 328 | E43: 12.6 | F43: 19.9 | G43: 24.6 | H43: 0.4 | I43: 1.1 | J43: 492 | K43: 238 | L43: 4.9 | M43: 755
B44: Tempe pasar goreng | C44: 42.9 | D44: 336 | E44: 20 | F44: 28 | G44: 7.8 | H44: 3.4 | I44: 1.3 | J44: 156 | K44: 350 | L44: 3 | M44: 20
C46: Air ⇲ | D46: Energi ⇲ | E46: Protein ⇲ | F46: Lemak ⇲ | G46: Abu ⇲ | H46: Karbohidrat ⇲ | I46: Serat Total ⇲ | J46: Gula Total ⇲ | K46: Kalsium (Ca) ⇲ | L46: Besi (Fe) ⇲ | M46: Magnesium (Mg) ⇲ | N46: Fosfor (P) ⇲ | O46: Kalium (K) ⇲ | P46: Natrium (Na) ⇲
B47: Nasi dan campuran bihun, rasa daging sapi, disiapkan dengan 80% margarin | C47: 70.93 | D47: 129 | E47: 2.82 | F47: 3.2 | G47: 1.01 | H47: 22.03 | I47: 0.6 | J47: - | K47: 10 | L47: 0.88 | M47: 10 | N47: 33 | O47: 48 | P47: 364
B48: Salad kentang dengan telur | C48: 70.99 | D48: 157 | E48: 1.96 | F48: 9.4 | G48: 1.47 | H48: 16.18 | I48: 1.3 | J48: 4.95 | K48: 15 | L48: 0.5 | M48: 15 | N48: 53 | O48: 242 | P48: 329
B49: Spaghettios, Spageti dengan Bakso | C49: 78.1 | D49: 95 | E49: 4.37 | F49: 2.78 | G49: 2.06 | H49: 12.7 | I49: 1.6 | J49: 3.17 | K49: 60 | L49: 1.43 | M49: 16 | N49: 79 | O49: 282 | P49: 238
B50: Apel, beku, tanpa pemanis, tidak dipanaskan | C50: 86.85 | D50: 48 | E50: 0.28 | F50: 0.32 | G50: 0.24 | H50: 12.31 | I50: 1.3 | J50: 10.1 | K50: 4 | L50: 0.18 | M50: 3 | N50: 8 | O50: 77 | P50: 3
B51: Apel, mentah, dengan kulit | C51: 85.56 | D51: 52 | E51: 0.26 | F51: 0.17 | G51: 0.19 | H51: 13.81 | I51: 2.4 | J51: 10.39 | K51: 6 | L51: 0.12 | M51: 5 | N51: 11 | O51: 107 | P51: 1
...

Sheet Copy of cakaran
B2: Konversi Sub-Kriteria → Nilai Numerik | I2: Matrik Ternormalisasi [R] | P2: Matrik Ternormalisasi Terbobot [Y] | W2: Jarak Dengan Solusi Ideal [Di] | AA2: Nilai Preferensi Untuk Setiap Alternatif [V]
B4: Nama Bahan Makanan | C4: Protein | D4: Lemak | E4: Karbohidrat | F4: Serat | G4: Natrium | I4: Nama Bahan Makanan | J4: Protein | K4: Lemak | L4: Karbohidrat | M4: Serat | N4: Natrium | P4: Nama Bahan Makanan | Q4: Protein / W=0,2 | R4: Lemak / W=0,15 | S4: Karbohidrat / W=0,1 | T4: Serat / W=0,25 | U4: Natrium / W=0,3 | W4: Nama Bahan Makanan | X4: Di+ | Y4: Di- | AA4: Nama Bahan Makanan | AB4: Vn
C5: (g) | D5: (g) | E5: (g) | F5: (g) | G5: (mg) | J5: (g) | K5: (g) | L5: (g) | M5: (g) | N5: (mg) | Q5: (g) | R5: (g) | S5: (g) | T5: (g) | U5: (mg)
B6: Nasi | C6: =IFS('data raw'!E7<=1, 1, 'data raw'!E7<=25, 2, 'data raw'!E7<=50, 3, 'data raw'!E7<=75, 4, TRUE, 5) -> 2 | D6: =IFS('data raw'!F7<=1, 1, 'data raw'!F7<=25, 2, 'data raw'!F7<=50, 3, 'data raw'!F7<=75, 4, TRUE, 5) -> 1 | E6: =IFS('data raw'!G7<=1, 1, 'data raw'!G7<=25, 2, 'data raw'!G7<=50, 3, 'data raw'!G7<=75, 4, TRUE, 5) -> 3 | F6: =IFS('data raw'!H7<=1, 1, 'data raw'!H7<=3, 2, 'data raw'!H7<=5, 3, 'data raw'!H7<=7, 4, TRUE, 5) -> 1 | G6: =IFS('data raw'!M7<=100, 5, 'data raw'!M7<=200, 4, 'data raw'!M7<=350, 3, 'data raw'!M7<=500, 2, TRUE, 1) -> 5 | I6: Nasi | J6: =C6/$C$32 -> 0.21566555 | K6: =D6/$D$32 -> 0.13018891 | L6: =E6/$E$32 -> 0.19011728 | M6: =F6/$F$32 -> 0.069006556 | N6: =G6/$G$32 -> 0.23836565 | P6: Nasi | Q6: =J6*0.2 -> 0.043133109 | R6: =K6*0.15 -> 0.019528337 | S6: =L6*0.1 -> 0.019011728 | T6: =M6*0.25 -> 0.017251639 | U6: =N6*0.3 -> 0.071509694 | W6: Nasi | X6: =SQRT(SUMPRODUCT((Q6:U6 - Q$31:U$31)^2)) -> 0.078420668 | Y6: =SQRT(SUMPRODUCT((Q6:U6 - Q$32:U$32)^2)) -> 0.045063296 | AA6: Nasi | AB6: =Y6 / (X6 + Y6) -> 0.36493237
B7: Biskuit | C7: =IFS('data raw'!E8<=1, 1, 'data raw'!E8<=25, 2, 'data raw'!E8<=50, 3, 'data raw'!E8<=75, 4, TRUE, 5) -> 2 | D7: =IFS('data raw'!F8<=1, 1, 'data raw'!F8<=25, 2, 'data raw'!F8<=50, 3, 'data raw'!F8<=75, 4, TRUE, 5) -> 2 | E7: =IFS('data raw'!G8<=1, 1, 'data raw'!G8<=25, 2, 'data raw'!G8<=50, 3, 'data raw'!G8<=75, 4, TRUE, 5) -> 5 | F7: =IFS('data raw'!H8<=1, 1, 'data raw'!H8<=3, 2, 'data raw'!H8<=5, 3, 'data raw'!H8<=7, 4, TRUE, 5) -> 2 | G7: =IFS('data raw'!M8<=100, 5, 'data raw'!M8<=200, 4, 'data raw'!M8<=350, 3, 'data raw'!M8<=500, 2, TRUE, 1) -> 3 | I7: Biskuit | J7: =C7/$C$32 -> 0.21566555 | K7: =D7/$D$32 -> 0.26037782 | L7: =E7/$E$32 -> 0.31686213 | M7: =F7/$F$32 -> 0.13801311 | N7: =G7/$G$32 -> 0.14301939 | P7: Biskuit | Q7: =J7*0.2 -> 0.043133109 | R7: =K7*0.15 -> 0.039056673 | S7: =L7*0.1 -> 0.031686213 | T7: =M7*0.25 -> 0.034503278 | U7: =N7*0.3 -> 0.042905817 | W7: Biskuit | X7: =SQRT(SUMPRODUCT((Q7:U7 - Q$31:U$31)^2)) -> 0.050758997 | Y7: =SQRT(SUMPRODUCT((Q7:U7 - Q$32:U$32)^2)) -> 0.048204967 | AA7: Biskuit | AB7: =Y7 / (X7 + Y7) -> 0.48709616
B8: Bubur tinotuan (Manado) | C8: =IFS('data raw'!E9<=1, 1, 'data raw'!E9<=25, 2, 'data raw'!E9<=50, 3, 'data raw'!E9<=75, 4, TRUE, 5) -> 2 | D8: =IFS('data raw'!F9<=1, 1, 'data raw'!F9<=25, 2, 'data raw'!F9<=50, 3, 'data raw'!F9<=75, 4, TRUE, 5) -> 1 | E8: =IFS('data raw'!G9<=1, 1, 'data raw'!G9<=25, 2, 'data raw'!G9<=50, 3, 'data raw'!G9<=75, 4, TRUE, 5) -> 2 | F8: =IFS('data raw'!H9<=1, 1, 'data raw'!H9<=3, 2, 'data raw'!H9<=5, 3, 'data raw'!H9<=7, 4, TRUE, 5) -> 5 | G8: =IFS('data raw'!M9<=100, 5, 'data raw'!M9<=200, 4, 'data raw'!M9<=350, 3, 'data raw'!M9<=500, 2, TRUE, 1) -> 2 | I8: Bubur tinotuan (Manado) | J8: =C8/$C$32 -> 0.21566555 | K8: =D8/$D$32 -> 0.13018891 | L8: =E8/$E$32 -> 0.12674485 | M8: =F8/$F$32 -> 0.34503278 | N8: =G8/$G$32 -> 0.095346259 | P8: Bubur tinotuan (Manado) | Q8: =J8*0.2 -> 0.043133109 | R8: =K8*0.15 -> 0.019528337 | S8: =L8*0.1 -> 0.012674485 | T8: =M8*0.25 -> 0.086258195 | U8: =N8*0.3 -> 0.028603878 | W8: Bubur tinotuan (Manado) | X8: =SQRT(SUMPRODUCT((Q8:U8 - Q$31:U$31)^2)) -> 0.038676579 | Y8: =SQRT(SUMPRODUCT((Q8:U8 - Q$32:U$32)^2)) -> 0.092700344 | AA8: Bubur tinotuan (Manado) | AB8: =Y8 / (X8 + Y8) -> 0.70560599 | AE8: RANK
B9: Mie bakso | C9: =IFS('data raw'!E10<=1, 1, 'data raw'!E10<=25, 2, 'data raw'!E10<=50, 3, 'data raw'!E10<=75, 4, TRUE, 5) -> 2 | D9: =IFS('data raw'!F10<=1, 1, 'data raw'!F10<=25, 2, 'data raw'!F10<=50, 3, 'data raw'!F10<=75, 4, TRUE, 5) -> 2 | E9: =IFS('data raw'!G10<=1, 1, 'data raw'!G10<=25, 2, 'data raw'!G10<=50, 3, 'data raw'!G10<=75, 4, TRUE, 5) -> 2 | F9: =IFS('data raw'!H10<=1, 1, 'data raw'!H10<=3, 2, 'data raw'!H10<=5, 3, 'data raw'!H10<=7, 4, TRUE, 5) -> 1 | G9: =IFS('data raw'!M10<=100, 5, 'data raw'!M10<=200, 4, 'data raw'!M10<=350, 3, 'data raw'!M10<=500, 2, TRUE, 1) -> 1 | I9: Mie bakso | J9: =C9/$C$32 -> 0.21566555 | K9: =D9/$D$32 -> 0.26037782 | L9: =E9/$E$32 -> 0.12674485 | M9: =F9/$F$32 -> 0.069006556 | N9: =G9/$G$32 -> 0.047673129 | P9: Mie bakso | Q9: =J9*0.2 -> 0.043133109 | R9: =K9*0.15 -> 0.039056673 | S9: =L9*0.1 -> 0.012674485 | T9: =M9*0.25 -> 0.017251639 | U9: =N9*0.3 -> 0.014301939 | W9: Mie bakso | X9: =SQRT(SUMPRODUCT((Q9:U9 - Q$31:U$31)^2)) -> 0.058815245 | Y9: =SQRT(SUMPRODUCT((Q9:U9 - Q$32:U$32)^2)) -> 0.06418099 | AA9: Mie bakso | AB9: =Y9 / (X9 + Y9) -> 0.52181264 | AE9: =IFERROR(__xludf.DUMMYFUNCTION("SORTN(AA6:AB29, 5, 0, AB6:AB29, FALSE)"),"Bubur tinotuan (Manado)") -> Bubur tinotuan (Manado) | AF9: =IFERROR(__xludf.DUMMYFUNCTION("""COMPUTED_VALUE"""),0.7056059915452259) -> 0.70560599
B10: Beras giling, mentah | C10: =IFS('data raw'!E11<=1, 1, 'data raw'!E11<=25, 2, 'data raw'!E11<=50, 3, 'data raw'!E11<=75, 4, TRUE, 5) -> 2 | D10: =IFS('data raw'!F11<=1, 1, 'data raw'!F11<=25, 2, 'data raw'!F11<=50, 3, 'data raw'!F11<=75, 4, TRUE, 5) -> 2 | E10: =IFS('data raw'!G11<=1, 1, 'data raw'!G11<=25, 2, 'data raw'!G11<=50, 3, 'data raw'!G11<=75, 4, TRUE, 5) -> 5 | F10: =IFS('data raw'!H11<=1, 1, 'data raw'!H11<=3, 2, 'data raw'!H11<=5, 3, 'data raw'!H11<=7, 4, TRUE, 5) -> 1 | G10: =IFS('data raw'!M11<=100, 5, 'data raw'!M11<=200, 4, 'data raw'!M11<=350, 3, 'data raw'!M11<=500, 2, TRUE, 1) -> 5 | I10: Beras giling, mentah | J10: =C10/$C$32 -> 0.21566555 | K10: =D10/$D$32 -> 0.26037782 | L10: =E10/$E$32 -> 0.31686213 | M10: =F10/$F$32 -> 0.069006556 | N10: =G10/$G$32 -> 0.23836565 | P10: Beras giling, mentah | Q10: =J10*0.2 -> 0.043133109 | R10: =K10*0.15 -> 0.039056673 | S10: =L10*0.1 -> 0.031686213 | T10: =M10*0.25 -> 0.017251639 | U10: =N10*0.3 -> 0.071509694 | W10: Beras giling, mentah | X10: =SQRT(SUMPRODUCT((Q10:U10 - Q$31:U$31)^2)) -> 0.079815503 | Y10: =SQRT(SUMPRODUCT((Q10:U10 - Q$32:U$32)^2)) -> 0.034755115 | AA10: Beras giling, mentah | AB10: =Y10 / (X10 + Y10) -> 0.30335103 | AE10: =IFERROR(__xludf.DUMMYFUNCTION("""COMPUTED_VALUE"""),"Keripik kentang") -> Keripik kentang | AF10: =IFERROR(__xludf.DUMMYFUNCTION("""COMPUTED_VALUE"""),0.6949316453040398) -> 0.69493165
B11: Beras jagung kuning, kering, mentah | C11: =IFS('data raw'!E12<=1, 1, 'data raw'!E12<=25, 2, 'data raw'!E12<=50, 3, 'data raw'!E12<=75, 4, TRUE, 5) -> 2 | D11: =IFS('data raw'!F12<=1, 1, 'data raw'!F12<=25, 2, 'data raw'!F12<=50, 3, 'data raw'!F12<=75, 4, TRUE, 5) -> 1 | E11: =IFS('data raw'!G12<=1, 1, 'data raw'!G12<=25, 2, 'data raw'!G12<=50, 3, 'data raw'!G12<=75, 4, TRUE, 5) -> 5 | F11: =IFS('data raw'!H12<=1, 1, 'data raw'!H12<=3, 2, 'data raw'!H12<=5, 3, 'data raw'!H12<=7, 4, TRUE, 5) -> 5 | G11: =IFS('data raw'!M12<=100, 5, 'data raw'!M12<=200, 4, 'data raw'!M12<=350, 3, 'data raw'!M12<=500, 2, TRUE, 1) -> 5 | I11: Beras jagung kuning, kering, mentah | J11: =C11/$C$32 -> 0.21566555 | K11: =D11/$D$32 -> 0.13018891 | L11: =E11/$E$32 -> 0.31686213 | M11: =F11/$F$32 -> 0.34503278 | N11: =G11/$G$32 -> 0.23836565 | P11: Beras jagung kuning, kering, mentah | Q11: =J11*0.2 -> 0.043133109 | R11: =K11*0.15 -> 0.019528337 | S11: =L11*0.1 -> 0.031686213 | T11: =M11*0.25 -> 0.086258195 | U11: =N11*0.3 -> 0.071509694 | W11: Beras jagung kuning, kering, mentah | X11: =SQRT(SUMPRODUCT((Q11:U11 - Q$31:U$31)^2)) -> 0.06482757 | Y11: =SQRT(SUMPRODUCT((Q11:U11 - Q$32:U$32)^2)) -> 0.084343883 | AA11: Beras jagung kuning, kering, mentah | AB11: =Y11 / (X11 + Y11) -> 0.56541571 | AE11: =IFERROR(__xludf.DUMMYFUNCTION("""COMPUTED_VALUE"""),"Kerupuk cumi goreng") -> Kerupuk cumi goreng | AF11: =IFERROR(__xludf.DUMMYFUNCTION("""COMPUTED_VALUE"""),0.6949316453040398) -> 0.69493165
B12: Batatas kelapa, ubi, bakar | C12: =IFS('data raw'!E13<=1, 1, 'data raw'!E13<=25, 2, 'data raw'!E13<=50, 3, 'data raw'!E13<=75, 4, TRUE, 5) -> 2 | D12: =IFS('data raw'!F13<=1, 1, 'data raw'!F13<=25, 2, 'data raw'!F13<=50, 3, 'data raw'!F13<=75, 4, TRUE, 5) -> 2 | E12: =IFS('data raw'!G13<=1, 1, 'data raw'!G13<=25, 2, 'data raw'!G13<=50, 3, 'data raw'!G13<=75, 4, TRUE, 5) -> 2 | F12: =IFS('data raw'!H13<=1, 1, 'data raw'!H13<=3, 2, 'data raw'!H13<=5, 3, 'data raw'!H13<=7, 4, TRUE, 5) -> 3 | G12: =IFS('data raw'!M13<=100, 5, 'data raw'!M13<=200, 4, 'data raw'!M13<=350, 3, 'data raw'!M13<=500, 2, TRUE, 1) -> 5 | I12: Batatas kelapa, ubi, bakar | J12: =C12/$C$32 -> 0.21566555 | K12: =D12/$D$32 -> 0.26037782 | L12: =E12/$E$32 -> 0.12674485 | M12: =F12/$F$32 -> 0.20701967 | N12: =G12/$G$32 -> 0.23836565 | P12: Batatas kelapa, ubi, bakar | Q12: =J12*0.2 -> 0.043133109 | R12: =K12*0.15 -> 0.039056673 | S12: =L12*0.1 -> 0.012674485 | T12: =M12*0.25 -> 0.051754917 | U12: =N12*0.3 -> 0.071509694 | W12: Batatas kelapa, ubi, bakar | X12: =SQRT(SUMPRODUCT((Q12:U12 - Q$31:U$31)^2)) -> 0.068177795 | Y12: =SQRT(SUMPRODUCT((Q12:U12 - Q$32:U$32)^2)) -> 0.045132565 | AA12: Batatas kelapa, ubi, bakar | AB12: =Y12 / (X12 + Y12) -> 0.39830925 | AE12: =IFERROR(__xludf.DUMMYFUNCTION("""COMPUTED_VALUE"""),"Kerupuk udang goreng") -> Kerupuk udang goreng | AF12: =IFERROR(__xludf.DUMMYFUNCTION("""COMPUTED_VALUE"""),0.6417296328989266) -> 0.64172963
B13: Batatas kelapa, ubi, kukus | C13: =IFS('data raw'!E14<=1, 1, 'data raw'!E14<=25, 2, 'data raw'!E14<=50, 3, 'data raw'!E14<=75, 4, TRUE, 5) -> 2 | D13: =IFS('data raw'!F14<=1, 1, 'data raw'!F14<=25, 2, 'data raw'!F14<=50, 3, 'data raw'!F14<=75, 4, TRUE, 5) -> 1 | E13: =IFS('data raw'!G14<=1, 1, 'data raw'!G14<=25, 2, 'data raw'!G14<=50, 3, 'data raw'!G14<=75, 4, TRUE, 5) -> 2 | F13: =IFS('data raw'!H14<=1, 1, 'data raw'!H14<=3, 2, 'data raw'!H14<=5, 3, 'data raw'!H14<=7, 4, TRUE, 5) -> 3 | G13: =IFS('data raw'!M14<=100, 5, 'data raw'!M14<=200, 4, 'data raw'!M14<=350, 3, 'data raw'!M14<=500, 2, TRUE, 1) -> 5 | I13: Batatas kelapa, ubi, kukus | J13: =C13/$C$32 -> 0.21566555 | K13: =D13/$D$32 -> 0.13018891 | L13: =E13/$E$32 -> 0.12674485 | M13: =F13/$F$32 -> 0.20701967 | N13: =G13/$G$32 -> 0.23836565 | P13: Batatas kelapa, ubi, kukus | Q13: =J13*0.2 -> 0.043133109 | R13: =K13*0.15 -> 0.019528337 | S13: =L13*0.1 -> 0.012674485 | T13: =M13*0.25 -> 0.051754917 | U13: =N13*0.3 -> 0.071509694 | W13: Batatas kelapa, ubi, kukus | X13: =SQRT(SUMPRODUCT((Q13:U13 - Q$31:U$31)^2)) -> 0.065321174 | Y13: =SQRT(SUMPRODUCT((Q13:U13 - Q$32:U$32)^2)) -> 0.056400498 | AA13: Batatas kelapa, ubi, kukus | AB13: =Y13 / (X13 + Y13) -> 0.46335625 | AE13: =IFERROR(__xludf.DUMMYFUNCTION("""COMPUTED_VALUE"""),"Kacang hijau, rebus") -> Kacang hijau, rebus | AF13: =IFERROR(__xludf.DUMMYFUNCTION("""COMPUTED_VALUE"""),0.5931318398996004) -> 0.59313184
B14: Batatas tali, ubi, rebus | C14: =IFS('data raw'!E15<=1, 1, 'data raw'!E15<=25, 2, 'data raw'!E15<=50, 3, 'data raw'!E15<=75, 4, TRUE, 5) -> 2 | D14: =IFS('data raw'!F15<=1, 1, 'data raw'!F15<=25, 2, 'data raw'!F15<=50, 3, 'data raw'!F15<=75, 4, TRUE, 5) -> 1 | E14: =IFS('data raw'!G15<=1, 1, 'data raw'!G15<=25, 2, 'data raw'!G15<=50, 3, 'data raw'!G15<=75, 4, TRUE, 5) -> 3 | F14: =IFS('data raw'!H15<=1, 1, 'data raw'!H15<=3, 2, 'data raw'!H15<=5, 3, 'data raw'!H15<=7, 4, TRUE, 5) -> 5 | G14: =IFS('data raw'!M15<=100, 5, 'data raw'!M15<=200, 4, 'data raw'!M15<=350, 3, 'data raw'!M15<=500, 2, TRUE, 1) -> 5 | I14: Batatas tali, ubi, rebus | J14: =C14/$C$32 -> 0.21566555 | K14: =D14/$D$32 -> 0.13018891 | L14: =E14/$E$32 -> 0.19011728 | M14: =F14/$F$32 -> 0.34503278 | N14: =G14/$G$32 -> 0.23836565 | P14: Batatas tali, ubi, rebus | Q14: =J14*0.2 -> 0.043133109 | R14: =K14*0.15 -> 0.019528337 | S14: =L14*0.1 -> 0.019011728 | T14: =M14*0.25 -> 0.086258195 | U14: =N14*0.3 -> 0.071509694 | W14: Batatas tali, ubi, rebus | X14: =SQRT(SUMPRODUCT((Q14:U14 - Q$31:U$31)^2)) -> 0.06605495 | Y14: =SQRT(SUMPRODUCT((Q14:U14 - Q$32:U$32)^2)) -> 0.082417264 | AA14: Batatas tali, ubi, rebus | AB14: =Y14 / (X14 + Y14) -> 0.55510228
B15: Belitung, talas, kukus | C15: =IFS('data raw'!E16<=1, 1, 'data raw'!E16<=25, 2, 'data raw'!E16<=50, 3, 'data raw'!E16<=75, 4, TRUE, 5) -> 2 | D15: =IFS('data raw'!F16<=1, 1, 'data raw'!F16<=25, 2, 'data raw'!F16<=50, 3, 'data raw'!F16<=75, 4, TRUE, 5) -> 1 | E15: =IFS('data raw'!G16<=1, 1, 'data raw'!G16<=25, 2, 'data raw'!G16<=50, 3, 'data raw'!G16<=75, 4, TRUE, 5) -> 3 | F15: =IFS('data raw'!H16<=1, 1, 'data raw'!H16<=3, 2, 'data raw'!H16<=5, 3, 'data raw'!H16<=7, 4, TRUE, 5) -> 1 | G15: =IFS('data raw'!M16<=100, 5, 'data raw'!M16<=200, 4, 'data raw'!M16<=350, 3, 'data raw'!M16<=500, 2, TRUE, 1) -> 5 | I15: Belitung, talas, kukus | J15: =C15/$C$32 -> 0.21566555 | K15: =D15/$D$32 -> 0.13018891 | L15: =E15/$E$32 -> 0.19011728 | M15: =F15/$F$32 -> 0.069006556 | N15: =G15/$G$32 -> 0.23836565 | P15: Belitung, talas, kukus | Q15: =J15*0.2 -> 0.043133109 | R15: =K15*0.15 -> 0.019528337 | S15: =L15*0.1 -> 0.019011728 | T15: =M15*0.25 -> 0.017251639 | U15: =N15*0.3 -> 0.071509694 | W15: Belitung, talas, kukus | X15: =SQRT(SUMPRODUCT((Q15:U15 - Q$31:U$31)^2)) -> 0.078420668 | Y15: =SQRT(SUMPRODUCT((Q15:U15 - Q$32:U$32)^2)) -> 0.045063296 | AA15: Belitung, talas, kukus | AB15: =Y15 / (X15 + Y15) -> 0.36493237
B16: Ketela pohon/singkong kukus | C16: =IFS('data raw'!E17<=1, 1, 'data raw'!E17<=25, 2, 'data raw'!E17<=50, 3, 'data raw'!E17<=75, 4, TRUE, 5) -> 2 | D16: =IFS('data raw'!F17<=1, 1, 'data raw'!F17<=25, 2, 'data raw'!F17<=50, 3, 'data raw'!F17<=75, 4, TRUE, 5) -> 1 | E16: =IFS('data raw'!G17<=1, 1, 'data raw'!G17<=25, 2, 'data raw'!G17<=50, 3, 'data raw'!G17<=75, 4, TRUE, 5) -> 3 | F16: =IFS('data raw'!H17<=1, 1, 'data raw'!H17<=3, 2, 'data raw'!H17<=5, 3, 'data raw'!H17<=7, 4, TRUE, 5) -> 2 | G16: =IFS('data raw'!M17<=100, 5, 'data raw'!M17<=200, 4, 'data raw'!M17<=350, 3, 'data raw'!M17<=500, 2, TRUE, 1) -> 5 | I16: Ketela pohon/singkong kukus | J16: =C16/$C$32 -> 0.21566555 | K16: =D16/$D$32 -> 0.13018891 | L16: =E16/$E$32 -> 0.19011728 | M16: =F16/$F$32 -> 0.13801311 | N16: =G16/$G$32 -> 0.23836565 | P16: Ketela pohon/singkong kukus | Q16: =J16*0.2 -> 0.043133109 | R16: =K16*0.15 -> 0.019528337 | S16: =L16*0.1 -> 0.019011728 | T16: =M16*0.25 -> 0.034503278 | U16: =N16*0.3 -> 0.071509694 | W16: Ketela pohon/singkong kukus | X16: =SQRT(SUMPRODUCT((Q16:U16 - Q$31:U$31)^2)) -> 0.069356383 | Y16: =SQRT(SUMPRODUCT((Q16:U16 - Q$32:U$32)^2)) -> 0.048252665 | AA16: Ketela pohon/singkong kukus | AB16: =Y16 / (X16 + Y16) -> 0.41028021
B17: Ubi jalar, kuning, kukus | C17: =IFS('data raw'!E18<=1, 1, 'data raw'!E18<=25, 2, 'data raw'!E18<=50, 3, 'data raw'!E18<=75, 4, TRUE, 5) -> 1 | D17: =IFS('data raw'!F18<=1, 1, 'data raw'!F18<=25, 2, 'data raw'!F18<=50, 3, 'data raw'!F18<=75, 4, TRUE, 5) -> 1 | E17: =IFS('data raw'!G18<=1, 1, 'data raw'!G18<=25, 2, 'data raw'!G18<=50, 3, 'data raw'!G18<=75, 4, TRUE, 5) -> 2 | F17: =IFS('data raw'!H18<=1, 1, 'data raw'!H18<=3, 2, 'data raw'!H18<=5, 3, 'data raw'!H18<=7, 4, TRUE, 5) -> 1 | G17: =IFS('data raw'!M18<=100, 5, 'data raw'!M18<=200, 4, 'data raw'!M18<=350, 3, 'data raw'!M18<=500, 2, TRUE, 1) -> 5 | I17: Ubi jalar, kuning, kukus | J17: =C17/$C$32 -> 0.10783277 | K17: =D17/$D$32 -> 0.13018891 | L17: =E17/$E$32 -> 0.12674485 | M17: =F17/$F$32 -> 0.069006556 | N17: =G17/$G$32 -> 0.23836565 | P17: Ubi jalar, kuning, kukus | Q17: =J17*0.2 -> 0.021566555 | R17: =K17*0.15 -> 0.019528337 | S17: =L17*0.1 -> 0.012674485 | T17: =M17*0.25 -> 0.017251639 | U17: =N17*0.3 -> 0.071509694 | W17: Ubi jalar, kuning, kukus | X17: =SQRT(SUMPRODUCT((Q17:U17 - Q$31:U$31)^2)) -> 0.088011097 | Y17: =SQRT(SUMPRODUCT((Q17:U17 - Q$32:U$32)^2)) -> 0.039056673 | AA17: Ubi jalar, kuning, kukus | AB17: =Y17 / (X17 + Y17) -> 0.30736884
B18: Ubi jalar tinta/ kemayung kukus | C18: =IFS('data raw'!E19<=1, 1, 'data raw'!E19<=25, 2, 'data raw'!E19<=50, 3, 'data raw'!E19<=75, 4, TRUE, 5) -> 1 | D18: =IFS('data raw'!F19<=1, 1, 'data raw'!F19<=25, 2, 'data raw'!F19<=50, 3, 'data raw'!F19<=75, 4, TRUE, 5) -> 1 | E18: =IFS('data raw'!G19<=1, 1, 'data raw'!G19<=25, 2, 'data raw'!G19<=50, 3, 'data raw'!G19<=75, 4, TRUE, 5) -> 3 | F18: =IFS('data raw'!H19<=1, 1, 'data raw'!H19<=3, 2, 'data raw'!H19<=5, 3, 'data raw'!H19<=7, 4, TRUE, 5) -> 2 | G18: =IFS('data raw'!M19<=100, 5, 'data raw'!M19<=200, 4, 'data raw'!M19<=350, 3, 'data raw'!M19<=500, 2, TRUE, 1) -> 5 | I18: Ubi jalar tinta/ kemayung kukus | J18: =C18/$C$32 -> 0.10783277 | K18: =D18/$D$32 -> 0.13018891 | L18: =E18/$E$32 -> 0.19011728 | M18: =F18/$F$32 -> 0.13801311 | N18: =G18/$G$32 -> 0.23836565 | P18: Ubi jalar tinta/ kemayung kukus | Q18: =J18*0.2 -> 0.021566555 | R18: =K18*0.15 -> 0.019528337 | S18: =L18*0.1 -> 0.019011728 | T18: =M18*0.25 -> 0.034503278 | U18: =N18*0.3 -> 0.071509694 | W18: Ubi jalar tinta/ kemayung kukus | X18: =SQRT(SUMPRODUCT((Q18:U18 - Q$31:U$31)^2)) -> 0.078775991 | Y18: =SQRT(SUMPRODUCT((Q18:U18 - Q$32:U$32)^2)) -> 0.04316484 | AA18: Ubi jalar tinta/ kemayung kukus | AB18: =Y18 / (X18 + Y18) -> 0.35398184
B19: Ubi jalar merah, segar | C19: =IFS('data raw'!E20<=1, 1, 'data raw'!E20<=25, 2, 'data raw'!E20<=50, 3, 'data raw'!E20<=75, 4, TRUE, 5) -> 2 | D19: =IFS('data raw'!F20<=1, 1, 'data raw'!F20<=25, 2, 'data raw'!F20<=50, 3, 'data raw'!F20<=75, 4, TRUE, 5) -> 1 | E19: =IFS('data raw'!G20<=1, 1, 'data raw'!G20<=25, 2, 'data raw'!G20<=50, 3, 'data raw'!G20<=75, 4, TRUE, 5) -> 3 | F19: =IFS('data raw'!H20<=1, 1, 'data raw'!H20<=3, 2, 'data raw'!H20<=5, 3, 'data raw'!H20<=7, 4, TRUE, 5) -> 1 | G19: =IFS('data raw'!M20<=100, 5, 'data raw'!M20<=200, 4, 'data raw'!M20<=350, 3, 'data raw'!M20<=500, 2, TRUE, 1) -> 5 | I19: Ubi jalar merah, segar | J19: =C19/$C$32 -> 0.21566555 | K19: =D19/$D$32 -> 0.13018891 | L19: =E19/$E$32 -> 0.19011728 | M19: =F19/$F$32 -> 0.069006556 | N19: =G19/$G$32 -> 0.23836565 | P19: Ubi jalar merah, segar | Q19: =J19*0.2 -> 0.043133109 | R19: =K19*0.15 -> 0.019528337 | S19: =L19*0.1 -> 0.019011728 | T19: =M19*0.25 -> 0.017251639 | U19: =N19*0.3 -> 0.071509694 | W19: Ubi jalar merah, segar | X19: =SQRT(SUMPRODUCT((Q19:U19 - Q$31:U$31)^2)) -> 0.078420668 | Y19: =SQRT(SUMPRODUCT((Q19:U19 - Q$32:U$32)^2)) -> 0.045063296 | AA19: Ubi jalar merah, segar | AB19: =Y19 / (X19 + Y19) -> 0.36493237
B20: Ubi jalar putih, segar | C20: =IFS('data raw'!E21<=1, 1, 'data raw'!E21<=25, 2, 'data raw'!E21<=50, 3, 'data raw'!E21<=75, 4, TRUE, 5) -> 1 | D20: =IFS('data raw'!F21<=1, 1, 'data raw'!F21<=25, 2, 'data raw'!F21<=50, 3, 'data raw'!F21<=75, 4, TRUE, 5) -> 1 | E20: =IFS('data raw'!G21<=1, 1, 'data raw'!G21<=25, 2, 'data raw'!G21<=50, 3, 'data raw'!G21<=75, 4, TRUE, 5) -> 2 | F20: =IFS('data raw'!H21<=1, 1, 'data raw'!H21<=3, 2, 'data raw'!H21<=5, 3, 'data raw'!H21<=7, 4, TRUE, 5) -> 3 | G20: =IFS('data raw'!M21<=100, 5, 'data raw'!M21<=200, 4, 'data raw'!M21<=350, 3, 'data raw'!M21<=500, 2, TRUE, 1) -> 5 | I20: Ubi jalar putih, segar | J20: =C20/$C$32 -> 0.10783277 | K20: =D20/$D$32 -> 0.13018891 | L20: =E20/$E$32 -> 0.12674485 | M20: =F20/$F$32 -> 0.20701967 | N20: =G20/$G$32 -> 0.23836565 | P20: Ubi jalar putih, segar | Q20: =J20*0.2 -> 0.021566555 | R20: =K20*0.15 -> 0.019528337 | S20: =L20*0.1 -> 0.012674485 | T20: =M20*0.25 -> 0.051754917 | U20: =N20*0.3 -> 0.071509694 | W20: Ubi jalar putih, segar | X20: =SQRT(SUMPRODUCT((Q20:U20 - Q$31:U$31)^2)) -> 0.075247622 | Y20: =SQRT(SUMPRODUCT((Q20:U20 - Q$32:U$32)^2)) -> 0.052114297 | AA20: Ubi jalar putih, segar | AB20: =Y20 / (X20 + Y20) -> 0.40918272
B21: Keripik kentang | C21: =IFS('data raw'!E22<=1, 1, 'data raw'!E22<=25, 2, 'data raw'!E22<=50, 3, 'data raw'!E22<=75, 4, TRUE, 5) -> 2 | D21: =IFS('data raw'!F22<=1, 1, 'data raw'!F22<=25, 2, 'data raw'!F22<=50, 3, 'data raw'!F22<=75, 4, TRUE, 5) -> 2 | E21: =IFS('data raw'!G22<=1, 1, 'data raw'!G22<=25, 2, 'data raw'!G22<=50, 3, 'data raw'!G22<=75, 4, TRUE, 5) -> 4 | F21: =IFS('data raw'!H22<=1, 1, 'data raw'!H22<=3, 2, 'data raw'!H22<=5, 3, 'data raw'!H22<=7, 4, TRUE, 5) -> 3 | G21: =IFS('data raw'!M22<=100, 5, 'data raw'!M22<=200, 4, 'data raw'!M22<=350, 3, 'data raw'!M22<=500, 2, TRUE, 1) -> 1 | I21: Keripik kentang | J21: =C21/$C$32 -> 0.21566555 | K21: =D21/$D$32 -> 0.26037782 | L21: =E21/$E$32 -> 0.2534897 | M21: =F21/$F$32 -> 0.20701967 | N21: =G21/$G$32 -> 0.047673129 | P21: Keripik kentang | Q21: =J21*0.2 -> 0.043133109 | R21: =K21*0.15 -> 0.039056673 | S21: =L21*0.1 -> 0.02534897 | T21: =M21*0.25 -> 0.051754917 | U21: =N21*0.3 -> 0.014301939 | W21: Keripik kentang | X21: =SQRT(SUMPRODUCT((Q21:U21 - Q$31:U$31)^2)) -> 0.032468436 | Y21: =SQRT(SUMPRODUCT((Q21:U21 - Q$32:U$32)^2)) -> 0.0739616 | AA21: Keripik kentang | AB21: =Y21 / (X21 + Y21) -> 0.69493165
B22: Keripik ubi | C22: =IFS('data raw'!E23<=1, 1, 'data raw'!E23<=25, 2, 'data raw'!E23<=50, 3, 'data raw'!E23<=75, 4, TRUE, 5) -> 1 | D22: =IFS('data raw'!F23<=1, 1, 'data raw'!F23<=25, 2, 'data raw'!F23<=50, 3, 'data raw'!F23<=75, 4, TRUE, 5) -> 2 | E22: =IFS('data raw'!G23<=1, 1, 'data raw'!G23<=25, 2, 'data raw'!G23<=50, 3, 'data raw'!G23<=75, 4, TRUE, 5) -> 4 | F22: =IFS('data raw'!H23<=1, 1, 'data raw'!H23<=3, 2, 'data raw'!H23<=5, 3, 'data raw'!H23<=7, 4, TRUE, 5) -> 5 | G22: =IFS('data raw'!M23<=100, 5, 'data raw'!M23<=200, 4, 'data raw'!M23<=350, 3, 'data raw'!M23<=500, 2, TRUE, 1) -> 5 | I22: Keripik ubi | J22: =C22/$C$32 -> 0.10783277 | K22: =D22/$D$32 -> 0.26037782 | L22: =E22/$E$32 -> 0.2534897 | M22: =F22/$F$32 -> 0.34503278 | N22: =G22/$G$32 -> 0.23836565 | P22: Keripik ubi | Q22: =J22*0.2 -> 0.021566555 | R22: =K22*0.15 -> 0.039056673 | S22: =L22*0.1 -> 0.02534897 | T22: =M22*0.25 -> 0.086258195 | U22: =N22*0.3 -> 0.071509694 | W22: Keripik ubi | X22: =SQRT(SUMPRODUCT((Q22:U22 - Q$31:U$31)^2)) -> 0.077585303 | Y22: =SQRT(SUMPRODUCT((Q22:U22 - Q$32:U$32)^2)) -> 0.072827902 | AA22: Keripik ubi | AB22: =Y22 / (X22 + Y22) -> 0.48418556
B23: Kerupuk cumi goreng | C23: =IFS('data raw'!E24<=1, 1, 'data raw'!E24<=25, 2, 'data raw'!E24<=50, 3, 'data raw'!E24<=75, 4, TRUE, 5) -> 2 | D23: =IFS('data raw'!F24<=1, 1, 'data raw'!F24<=25, 2, 'data raw'!F24<=50, 3, 'data raw'!F24<=75, 4, TRUE, 5) -> 2 | E23: =IFS('data raw'!G24<=1, 1, 'data raw'!G24<=25, 2, 'data raw'!G24<=50, 3, 'data raw'!G24<=75, 4, TRUE, 5) -> 4 | F23: =IFS('data raw'!H24<=1, 1, 'data raw'!H24<=3, 2, 'data raw'!H24<=5, 3, 'data raw'!H24<=7, 4, TRUE, 5) -> 3 | G23: =IFS('data raw'!M24<=100, 5, 'data raw'!M24<=200, 4, 'data raw'!M24<=350, 3, 'data raw'!M24<=500, 2, TRUE, 1) -> 1 | I23: Kerupuk cumi goreng | J23: =C23/$C$32 -> 0.21566555 | K23: =D23/$D$32 -> 0.26037782 | L23: =E23/$E$32 -> 0.2534897 | M23: =F23/$F$32 -> 0.20701967 | N23: =G23/$G$32 -> 0.047673129 | P23: Kerupuk cumi goreng | Q23: =J23*0.2 -> 0.043133109 | R23: =K23*0.15 -> 0.039056673 | S23: =L23*0.1 -> 0.02534897 | T23: =M23*0.25 -> 0.051754917 | U23: =N23*0.3 -> 0.014301939 | W23: Kerupuk cumi goreng | X23: =SQRT(SUMPRODUCT((Q23:U23 - Q$31:U$31)^2)) -> 0.032468436 | Y23: =SQRT(SUMPRODUCT((Q23:U23 - Q$32:U$32)^2)) -> 0.0739616 | AA23: Kerupuk cumi goreng | AB23: =Y23 / (X23 + Y23) -> 0.69493165
B24: Kerupuk udang goreng | C24: =IFS('data raw'!E25<=1, 1, 'data raw'!E25<=25, 2, 'data raw'!E25<=50, 3, 'data raw'!E25<=75, 4, TRUE, 5) -> 2 | D24: =IFS('data raw'!F25<=1, 1, 'data raw'!F25<=25, 2, 'data raw'!F25<=50, 3, 'data raw'!F25<=75, 4, TRUE, 5) -> 2 | E24: =IFS('data raw'!G25<=1, 1, 'data raw'!G25<=25, 2, 'data raw'!G25<=50, 3, 'data raw'!G25<=75, 4, TRUE, 5) -> 4 | F24: =IFS('data raw'!H25<=1, 1, 'data raw'!H25<=3, 2, 'data raw'!H25<=5, 3, 'data raw'!H25<=7, 4, TRUE, 5) -> 3 | G24: =IFS('data raw'!M25<=100, 5, 'data raw'!M25<=200, 4, 'data raw'!M25<=350, 3, 'data raw'!M25<=500, 2, TRUE, 1) -> 2 | I24: Kerupuk udang goreng | J24: =C24/$C$32 -> 0.21566555 | K24: =D24/$D$32 -> 0.26037782 | L24: =E24/$E$32 -> 0.2534897 | M24: =F24/$F$32 -> 0.20701967 | N24: =G24/$G$32 -> 0.095346259 | P24: Kerupuk udang goreng | Q24: =J24*0.2 -> 0.043133109 | R24: =K24*0.15 -> 0.039056673 | S24: =L24*0.1 -> 0.02534897 | T24: =M24*0.25 -> 0.051754917 | U24: =N24*0.3 -> 0.028603878 | W24: Kerupuk udang goreng | X24: =SQRT(SUMPRODUCT((Q24:U24 - Q$31:U$31)^2)) -> 0.035478793 | Y24: =SQRT(SUMPRODUCT((Q24:U24 - Q$32:U$32)^2)) -> 0.063549194 | AA24: Kerupuk udang goreng | AB24: =Y24 / (X24 + Y24) -> 0.64172963
B25: Kue putu singkong | C25: =IFS('data raw'!E26<=1, 1, 'data raw'!E26<=25, 2, 'data raw'!E26<=50, 3, 'data raw'!E26<=75, 4, TRUE, 5) -> 2 | D25: =IFS('data raw'!F26<=1, 1, 'data raw'!F26<=25, 2, 'data raw'!F26<=50, 3, 'data raw'!F26<=75, 4, TRUE, 5) -> 1 | E25: =IFS('data raw'!G26<=1, 1, 'data raw'!G26<=25, 2, 'data raw'!G26<=50, 3, 'data raw'!G26<=75, 4, TRUE, 5) -> 4 | F25: =IFS('data raw'!H26<=1, 1, 'data raw'!H26<=3, 2, 'data raw'!H26<=5, 3, 'data raw'!H26<=7, 4, TRUE, 5) -> 2 | G25: =IFS('data raw'!M26<=100, 5, 'data raw'!M26<=200, 4, 'data raw'!M26<=350, 3, 'data raw'!M26<=500, 2, TRUE, 1) -> 5 | I25: Kue putu singkong | J25: =C25/$C$32 -> 0.21566555 | K25: =D25/$D$32 -> 0.13018891 | L25: =E25/$E$32 -> 0.2534897 | M25: =F25/$F$32 -> 0.13801311 | N25: =G25/$G$32 -> 0.23836565 | P25: Kue putu singkong | Q25: =J25*0.2 -> 0.043133109 | R25: =K25*0.15 -> 0.019528337 | S25: =L25*0.1 -> 0.02534897 | T25: =M25*0.25 -> 0.034503278 | U25: =N25*0.3 -> 0.071509694 | W25: Kue putu singkong | X25: =SQRT(SUMPRODUCT((Q25:U25 - Q$31:U$31)^2)) -> 0.068482304 | Y25: =SQRT(SUMPRODUCT((Q25:U25 - Q$32:U$32)^2)) -> 0.049485368 | AA25: Kue putu singkong | AB25: =Y25 / (X25 + Y25) -> 0.41948245
... B29: Kacang kedelai, rebus | C29: =IFS('data raw'!E30<=1, 1, 'data raw'!E30<=25, 2, 'data raw'!E30<=50, 3, 'data raw'!E30<=75, 4, TRUE, 5) -> 2 | D29: =IFS('data raw'!F30<=1, 1, 'data raw'!F30<=25, 2, 'data raw'!F30<=50, 3, 'data raw'!F30<=75, 4, TRUE, 5) -> 2 | E29: =IFS('data raw'!G30<=1, 1, 'data raw'!G30<=25, 2, 'data raw'!G30<=50, 3, 'data raw'!G30<=75, 4, TRUE, 5) -> 2 | F29: =IFS('data raw'!H30<=1, 1, 'data raw'!H30<=3, 2, 'data raw'!H30<=5, 3, 'data raw'!H30<=7, 4, TRUE, 5) -> 2 | G29: =IFS('data raw'!M30<=100, 5, 'data raw'!M30<=200, 4, 'data raw'!M30<=350, 3, 'data raw'!M30<=500, 2, TRUE, 1) -> 4 | I29: Kacang kedelai, rebus | J29: =C29/$C$32 -> 0.21566555 | K29: =D29/$D$32 -> 0.26037782 | L29: =E29/$E$32 -> 0.12674485 | M29: =F29/$F$32 -> 0.13801311 | N29: =G29/$G$32 -> 0.19069252 | P29: Kacang kedelai, rebus | Q29: =J29*0.2 -> 0.043133109 | R29: =K29*0.15 -> 0.039056673 | S29: =L29*0.1 -> 0.012674485 | T29: =M29*0.25 -> 0.034503278 | U29: =N29*0.3 -> 0.057207755 | W29: Kacang kedelai, rebus | X29: =SQRT(SUMPRODUCT((Q29:U29 - Q$31:U$31)^2)) -> 0.062933686 | Y29: =SQRT(SUMPRODUCT((Q29:U29 - Q$32:U$32)^2)) -> 0.036723789 | AA29: Kacang kedelai, rebus | AB29: =Y29 / (X29 + Y29) -> 0.3685001
B31: x^2 | C31: =SUMPRODUCT(C6:C29^2) -> 86 | D31: =SUMPRODUCT(D6:D29^2) -> 59 | E31: =SUMPRODUCT(E6:E29^2) -> 249 | F31: =SUMPRODUCT(F6:F29^2) -> 210 | G31: =SUMPRODUCT(G6:G29^2) -> 440 | P31: A+ | Q31: =MAX(Q6:Q29) -> 0.064699664 | R31: =MIN(R5:R28) -> 0.019528337 | S31: =MAX(S6:S29) -> 0.031686213 | T31: =MAX(Q6:Q29) -> 0.064699664 | U31: =MIN(U5:U28) -> 0.014301939
B32: x^2 | C32: =SQRT(SUMPRODUCT(C6:C29^2)) -> 9.2736185 | D32: =SQRT(SUMPRODUCT(D6:D29^2)) -> 7.6811457 | E32: =SQRT(SUMPRODUCT(E6:E29^2)) -> 15.779734 | F32: =SQRT(SUMPRODUCT(F6:F29^2)) -> 14.491377 | G32: =SQRT(SUMPRODUCT(G6:G29^2)) -> 20.976177 | P32: A- | Q32: =MIN(Q6:Q29) -> 0.021566555 | R32: =MAX(R6:R29) -> 0.05858501 | S32: =MIN(S6:S29) -> 0.012674485 | T32: =MIN(T6:T29) -> 0.017251639 | U32: =MAX(U6:U29) -> 0.071509694

Sheet trial_k
B2: Konversi Sub-Kriteria → Nilai Numerik | I2: Matrik Ternormalisasi [R] | P2: Matrik Ternormalisasi Terbobot [Y] | W2: Jarak Dengan Solusi Ideal [Di] | AA2: Nilai Preferensi Untuk Setiap Alternatif [V]
B4: Nama Bahan Makanan | C4: Protein | D4: Lemak | E4: Karbohidrat | F4: Serat | G4: Natrium | I4: Nama Bahan Makanan | J4: Protein | K4: Lemak | L4: Karbohidrat | M4: Serat | N4: Natrium | P4: Nama Bahan Makanan | Q4: Protein / W=0,05 | R4: Lemak / W=0,25 | S4: Karbohidrat / W=0,2 | T4: Serat / W=0,1 | U4: Natrium / W=0,4 | W4: Nama Bahan Makanan | X4: Di+ | Y4: Di- | AA4: Nama Bahan Makanan | AB4: Vn
C5: (g) | D5: (g) | E5: (g) | F5: (g) | G5: (mg) | J5: (g) | K5: (g) | L5: (g) | M5: (g) | N5: (mg) | Q5: (g) | R5: (g) | S5: (g) | T5: (g) | U5: (mg)
B6: Nasi | C6: =IFS('data raw'!E7<=1, 1, 'data raw'!E7<=25, 2, 'data raw'!E7<=50, 3, 'data raw'!E7<=75, 4, TRUE, 5) -> 2 | D6: =IFS('data raw'!F7<=1, 1, 'data raw'!F7<=25, 2, 'data raw'!F7<=50, 3, 'data raw'!F7<=75, 4, TRUE, 5) -> 1 | E6: =IFS('data raw'!G7<=1, 1, 'data raw'!G7<=25, 2, 'data raw'!G7<=50, 3, 'data raw'!G7<=75, 4, TRUE, 5) -> 3 | F6: =IFS('data raw'!H7<=1, 1, 'data raw'!H7<=3, 2, 'data raw'!H7<=5, 3, 'data raw'!H7<=7, 4, TRUE, 5) -> 1 | G6: =IFS('data raw'!M7<=100, 5, 'data raw'!M7<=200, 4, 'data raw'!M7<=350, 3, 'data raw'!M7<=500, 2, TRUE, 1) -> 5 | I6: Nasi | J6: =C6/$C$32 -> 0.21566555 | K6: =D6/$D$32 -> 0.13018891 | L6: =E6/$E$32 -> 0.19011728 | M6: =F6/$F$32 -> 0.069006556 | N6: =G6/$G$32 -> 0.23836565 | P6: Nasi | Q6: =J6*0.05 -> 0.010783277 | R6: =K6*0.25 -> 0.032547228 | S6: =L6*0.2 -> 0.038023455 | T6: =M6*0.1 -> 0.0069006556 | U6: =N6*0.4 -> 0.095346259 | W6: Nasi | X6: =SQRT(SUMPRODUCT((Q6:U6 - Q$31:U$31)^2)) -> 0.081091515 | Y6: =SQRT(SUMPRODUCT((Q6:U6 - Q$32:U$32)^2)) -> 0.066535708 | AA6: Nasi | AB6: =Y6 / (X6 + Y6) -> 0.4507008
B7: Biskuit | C7: =IFS('data raw'!E8<=1, 1, 'data raw'!E8<=25, 2, 'data raw'!E8<=50, 3, 'data raw'!E8<=75, 4, TRUE, 5) -> 2 | D7: =IFS('data raw'!F8<=1, 1, 'data raw'!F8<=25, 2, 'data raw'!F8<=50, 3, 'data raw'!F8<=75, 4, TRUE, 5) -> 2 | E7: =IFS('data raw'!G8<=1, 1, 'data raw'!G8<=25, 2, 'data raw'!G8<=50, 3, 'data raw'!G8<=75, 4, TRUE, 5) -> 5 | F7: =IFS('data raw'!H8<=1, 1, 'data raw'!H8<=3, 2, 'data raw'!H8<=5, 3, 'data raw'!H8<=7, 4, TRUE, 5) -> 2 | G7: =IFS('data raw'!M8<=100, 5, 'data raw'!M8<=200, 4, 'data raw'!M8<=350, 3, 'data raw'!M8<=500, 2, TRUE, 1) -> 3 | I7: Biskuit | J7: =C7/$C$32 -> 0.21566555 | K7: =D7/$D$32 -> 0.26037782 | L7: =E7/$E$32 -> 0.31686213 | M7: =F7/$F$32 -> 0.13801311 | N7: =G7/$G$32 -> 0.14301939 | P7: Biskuit | Q7: =J7*0.05 -> 0.010783277 | R7: =K7*0.25 -> 0.065094455 | S7: =L7*0.2 -> 0.063372425 | T7: =M7*0.1 -> 0.013801311 | U7: =N7*0.4 -> 0.057207755 | W7: Biskuit | X7: =SQRT(SUMPRODUCT((Q7:U7 - Q$31:U$31)^2)) -> 0.050483376 | Y7: =SQRT(SUMPRODUCT((Q7:U7 - Q$32:U$32)^2)) -> 0.063532192 | AA7: Biskuit | AB7: =Y7 / (X7 + Y7) -> 0.55722383
B8: Bubur tinotuan (Manado) | C8: =IFS('data raw'!E9<=1, 1, 'data raw'!E9<=25, 2, 'data raw'!E9<=50, 3, 'data raw'!E9<=75, 4, TRUE, 5) -> 2 | D8: =IFS('data raw'!F9<=1, 1, 'data raw'!F9<=25, 2, 'data raw'!F9<=50, 3, 'data raw'!F9<=75, 4, TRUE, 5) -> 1 | E8: =IFS('data raw'!G9<=1, 1, 'data raw'!G9<=25, 2, 'data raw'!G9<=50, 3, 'data raw'!G9<=75, 4, TRUE, 5) -> 2 | F8: =IFS('data raw'!H9<=1, 1, 'data raw'!H9<=3, 2, 'data raw'!H9<=5, 3, 'data raw'!H9<=7, 4, TRUE, 5) -> 5 | G8: =IFS('data raw'!M9<=100, 5, 'data raw'!M9<=200, 4, 'data raw'!M9<=350, 3, 'data raw'!M9<=500, 2, TRUE, 1) -> 2 | I8: Bubur tinotuan (Manado) | J8: =C8/$C$32 -> 0.21566555 | K8: =D8/$D$32 -> 0.13018891 | L8: =E8/$E$32 -> 0.12674485 | M8: =F8/$F$32 -> 0.34503278 | N8: =G8/$G$32 -> 0.095346259 | P8: Bubur tinotuan (Manado) | Q8: =J8*0.05 -> 0.010783277 | R8: =K8*0.25 -> 0.032547228 | S8: =L8*0.2 -> 0.02534897 | T8: =M8*0.1 -> 0.034503278 | U8: =N8*0.4 -> 0.038138504 | W8: Bubur tinotuan (Manado) | X8: =SQRT(SUMPRODUCT((Q8:U8 - Q$31:U$31)^2)) -> 0.046630656 | Y8: =SQRT(SUMPRODUCT((Q8:U8 - Q$32:U$32)^2)) -> 0.091109769 | AA8: Bubur tinotuan (Manado) | AB8: =Y8 / (X8 + Y8) -> 0.66145991 | AE8: RANK
B9: Mie bakso | C9: =IFS('data raw'!E10<=1, 1, 'data raw'!E10<=25, 2, 'data raw'!E10<=50, 3, 'data raw'!E10<=75, 4, TRUE, 5) -> 2 | D9: =IFS('data raw'!F10<=1, 1, 'data raw'!F10<=25, 2, 'data raw'!F10<=50, 3, 'data raw'!F10<=75, 4, TRUE, 5) -> 2 | E9: =IFS('data raw'!G10<=1, 1, 'data raw'!G10<=25, 2, 'data raw'!G10<=50, 3, 'data raw'!G10<=75, 4, TRUE, 5) -> 2 | F9: =IFS('data raw'!H10<=1, 1, 'data raw'!H10<=3, 2, 'data raw'!H10<=5, 3, 'data raw'!H10<=7, 4, TRUE, 5) -> 1 | G9: =IFS('data raw'!M10<=100, 5, 'data raw'!M10<=200, 4, 'data raw'!M10<=350, 3, 'data raw'!M10<=500, 2, TRUE, 1) -> 1 | I9: Mie bakso | J9: =C9/$C$32 -> 0.21566555 | K9: =D9/$D$32 -> 0.26037782 | L9: =E9/$E$32 -> 0.12674485 | M9: =F9/$F$32 -> 0.069006556 | N9: =G9/$G$32 -> 0.047673129 | P9: Mie bakso | Q9: =J9*0.05 -> 0.010783277 | R9: =K9*0.25 -> 0.065094455 | S9: =L9*0.2 -> 0.02534897 | T9: =M9*0.1 -> 0.0069006556 | U9: =N9*0.4 -> 0.019069252 | W9: Mie bakso | X9: =SQRT(SUMPRODUCT((Q9:U9 - Q$31:U$31)^2)) -> 0.051187761 | Y9: =SQRT(SUMPRODUCT((Q9:U9 - Q$32:U$32)^2)) -> 0.083105798 | AA9: Mie bakso | AB9: =Y9 / (X9 + Y9) -> 0.61883681 | AE9: =IFERROR(__xludf.DUMMYFUNCTION("SORTN(AA6:AB29, 5, 0, AB6:AB29, FALSE)"),"Keripik kentang") -> Keripik kentang | AF9: =IFERROR(__xludf.DUMMYFUNCTION("""COMPUTED_VALUE"""),0.7117407521496113) -> 0.71174075
B10: Beras giling, mentah | C10: =IFS('data raw'!E11<=1, 1, 'data raw'!E11<=25, 2, 'data raw'!E11<=50, 3, 'data raw'!E11<=75, 4, TRUE, 5) -> 2 | D10: =IFS('data raw'!F11<=1, 1, 'data raw'!F11<=25, 2, 'data raw'!F11<=50, 3, 'data raw'!F11<=75, 4, TRUE, 5) -> 2 | E10: =IFS('data raw'!G11<=1, 1, 'data raw'!G11<=25, 2, 'data raw'!G11<=50, 3, 'data raw'!G11<=75, 4, TRUE, 5) -> 5 | F10: =IFS('data raw'!H11<=1, 1, 'data raw'!H11<=3, 2, 'data raw'!H11<=5, 3, 'data raw'!H11<=7, 4, TRUE, 5) -> 1 | G10: =IFS('data raw'!M11<=100, 5, 'data raw'!M11<=200, 4, 'data raw'!M11<=350, 3, 'data raw'!M11<=500, 2, TRUE, 1) -> 5 | I10: Beras giling, mentah | J10: =C10/$C$32 -> 0.21566555 | K10: =D10/$D$32 -> 0.26037782 | L10: =E10/$E$32 -> 0.31686213 | M10: =F10/$F$32 -> 0.069006556 | N10: =G10/$G$32 -> 0.23836565 | P10: Beras giling, mentah | Q10: =J10*0.05 -> 0.010783277 | R10: =K10*0.25 -> 0.065094455 | S10: =L10*0.2 -> 0.063372425 | T10: =M10*0.1 -> 0.0069006556 | U10: =N10*0.4 -> 0.095346259 | W10: Beras giling, mentah | X10: =SQRT(SUMPRODUCT((Q10:U10 - Q$31:U$31)^2)) -> 0.083621681 | Y10: =SQRT(SUMPRODUCT((Q10:U10 - Q$32:U$32)^2)) -> 0.050340589 | AA10: Beras giling, mentah | AB10: =Y10 / (X10 + Y10) -> 0.37578185 | AE10: =IFERROR(__xludf.DUMMYFUNCTION("""COMPUTED_VALUE"""),"Kerupuk cumi goreng") -> Kerupuk cumi goreng | AF10: =IFERROR(__xludf.DUMMYFUNCTION("""COMPUTED_VALUE"""),0.7117407521496113) -> 0.71174075
B11: Beras jagung kuning, kering, mentah | C11: =IFS('data raw'!E12<=1, 1, 'data raw'!E12<=25, 2, 'data raw'!E12<=50, 3, 'data raw'!E12<=75, 4, TRUE, 5) -> 2 | D11: =IFS('data raw'!F12<=1, 1, 'data raw'!F12<=25, 2, 'data raw'!F12<=50, 3, 'data raw'!F12<=75, 4, TRUE, 5) -> 1 | E11: =IFS('data raw'!G12<=1, 1, 'data raw'!G12<=25, 2, 'data raw'!G12<=50, 3, 'data raw'!G12<=75, 4, TRUE, 5) -> 5 | F11: =IFS('data raw'!H12<=1, 1, 'data raw'!H12<=3, 2, 'data raw'!H12<=5, 3, 'data raw'!H12<=7, 4, TRUE, 5) -> 5 | G11: =IFS('data raw'!M12<=100, 5, 'data raw'!M12<=200, 4, 'data raw'!M12<=350, 3, 'data raw'!M12<=500, 2, TRUE, 1) -> 5 | I11: Beras jagung kuning, kering, mentah | J11: =C11/$C$32 -> 0.21566555 | K11: =D11/$D$32 -> 0.13018891 | L11: =E11/$E$32 -> 0.31686213 | M11: =F11/$F$32 -> 0.34503278 | N11: =G11/$G$32 -> 0.23836565 | P11: Beras jagung kuning, kering, mentah | Q11: =J11*0.05 -> 0.010783277 | R11: =K11*0.25 -> 0.032547228 | S11: =L11*0.2 -> 0.063372425 | T11: =M11*0.1 -> 0.034503278 | U11: =N11*0.4 -> 0.095346259 | W11: Beras jagung kuning, kering, mentah | X11: =SQRT(SUMPRODUCT((Q11:U11 - Q$31:U$31)^2)) -> 0.078633202 | Y11: =SQRT(SUMPRODUCT((Q11:U11 - Q$32:U$32)^2)) -> 0.080461455 | AA11: Beras jagung kuning, kering, mentah | AB11: =Y11 / (X11 + Y11) -> 0.5057458 | AE11: =IFERROR(__xludf.DUMMYFUNCTION("""COMPUTED_VALUE"""),"Kacang hijau, rebus") -> Kacang hijau, rebus | AF11: =IFERROR(__xludf.DUMMYFUNCTION("""COMPUTED_VALUE"""),0.6697814265658962) -> 0.66978143
B12: Batatas kelapa, ubi, bakar | C12: =IFS('data raw'!E13<=1, 1, 'data raw'!E13<=25, 2, 'data raw'!E13<=50, 3, 'data raw'!E13<=75, 4, TRUE, 5) -> 2 | D12: =IFS('data raw'!F13<=1, 1, 'data raw'!F13<=25, 2, 'data raw'!F13<=50, 3, 'data raw'!F13<=75, 4, TRUE, 5) -> 2 | E12: =IFS('data raw'!G13<=1, 1, 'data raw'!G13<=25, 2, 'data raw'!G13<=50, 3, 'data raw'!G13<=75, 4, TRUE, 5) -> 2 | F12: =IFS('data raw'!H13<=1, 1, 'data raw'!H13<=3, 2, 'data raw'!H13<=5, 3, 'data raw'!H13<=7, 4, TRUE, 5) -> 3 | G12: =IFS('data raw'!M13<=100, 5, 'data raw'!M13<=200, 4, 'data raw'!M13<=350, 3, 'data raw'!M13<=500, 2, TRUE, 1) -> 5 | I12: Batatas kelapa, ubi, bakar | J12: =C12/$C$32 -> 0.21566555 | K12: =D12/$D$32 -> 0.26037782 | L12: =E12/$E$32 -> 0.12674485 | M12: =F12/$F$32 -> 0.20701967 | N12: =G12/$G$32 -> 0.23836565 | P12: Batatas kelapa, ubi, bakar | Q12: =J12*0.05 -> 0.010783277 | R12: =K12*0.25 -> 0.065094455 | S12: =L12*0.2 -> 0.02534897 | T12: =M12*0.1 -> 0.020701967 | U12: =N12*0.4 -> 0.095346259 | W12: Batatas kelapa, ubi, bakar | X12: =SQRT(SUMPRODUCT((Q12:U12 - Q$31:U$31)^2)) -> 0.091503284 | Y12: =SQRT(SUMPRODUCT((Q12:U12 - Q$32:U$32)^2)) -> 0.035761264 | AA12: Batatas kelapa, ubi, bakar | AB12: =Y12 / (X12 + Y12) -> 0.28099942 | AE12: =IFERROR(__xludf.DUMMYFUNCTION("""COMPUTED_VALUE"""),"Bubur tinotuan (Manado)") -> Bubur tinotuan (Manado) | AF12: =IFERROR(__xludf.DUMMYFUNCTION("""COMPUTED_VALUE"""),0.6614599062196438) -> 0.66145991
B13: Batatas kelapa, ubi, kukus | C13: =IFS('data raw'!E14<=1, 1, 'data raw'!E14<=25, 2, 'data raw'!E14<=50, 3, 'data raw'!E14<=75, 4, TRUE, 5) -> 2 | D13: =IFS('data raw'!F14<=1, 1, 'data raw'!F14<=25, 2, 'data raw'!F14<=50, 3, 'data raw'!F14<=75, 4, TRUE, 5) -> 1 | E13: =IFS('data raw'!G14<=1, 1, 'data raw'!G14<=25, 2, 'data raw'!G14<=50, 3, 'data raw'!G14<=75, 4, TRUE, 5) -> 2 | F13: =IFS('data raw'!H14<=1, 1, 'data raw'!H14<=3, 2, 'data raw'!H14<=5, 3, 'data raw'!H14<=7, 4, TRUE, 5) -> 3 | G13: =IFS('data raw'!M14<=100, 5, 'data raw'!M14<=200, 4, 'data raw'!M14<=350, 3, 'data raw'!M14<=500, 2, TRUE, 1) -> 5 | I13: Batatas kelapa, ubi, kukus | J13: =C13/$C$32 -> 0.21566555 | K13: =D13/$D$32 -> 0.13018891 | L13: =E13/$E$32 -> 0.12674485 | M13: =F13/$F$32 -> 0.20701967 | N13: =G13/$G$32 -> 0.23836565 | P13: Batatas kelapa, ubi, kukus | Q13: =J13*0.05 -> 0.010783277 | R13: =K13*0.25 -> 0.032547228 | S13: =L13*0.2 -> 0.02534897 | T13: =M13*0.1 -> 0.020701967 | U13: =N13*0.4 -> 0.095346259 | W13: Batatas kelapa, ubi, kukus | X13: =SQRT(SUMPRODUCT((Q13:U13 - Q$31:U$31)^2)) -> 0.085519173 | Y13: =SQRT(SUMPRODUCT((Q13:U13 - Q$32:U$32)^2)) -> 0.066759524 | AA13: Batatas kelapa, ubi, kukus | AB13: =Y13 / (X13 + Y13) -> 0.43840357 | AE13: =IFERROR(__xludf.DUMMYFUNCTION("""COMPUTED_VALUE"""),"Kerupuk udang goreng") -> Kerupuk udang goreng | AF13: =IFERROR(__xludf.DUMMYFUNCTION("""COMPUTED_VALUE"""),0.6407240458606575) -> 0.64072405
B14: Batatas tali, ubi, rebus | C14: =IFS('data raw'!E15<=1, 1, 'data raw'!E15<=25, 2, 'data raw'!E15<=50, 3, 'data raw'!E15<=75, 4, TRUE, 5) -> 2 | D14: =IFS('data raw'!F15<=1, 1, 'data raw'!F15<=25, 2, 'data raw'!F15<=50, 3, 'data raw'!F15<=75, 4, TRUE, 5) -> 1 | E14: =IFS('data raw'!G15<=1, 1, 'data raw'!G15<=25, 2, 'data raw'!G15<=50, 3, 'data raw'!G15<=75, 4, TRUE, 5) -> 3 | F14: =IFS('data raw'!H15<=1, 1, 'data raw'!H15<=3, 2, 'data raw'!H15<=5, 3, 'data raw'!H15<=7, 4, TRUE, 5) -> 5 | G14: =IFS('data raw'!M15<=100, 5, 'data raw'!M15<=200, 4, 'data raw'!M15<=350, 3, 'data raw'!M15<=500, 2, TRUE, 1) -> 5 | I14: Batatas tali, ubi, rebus | J14: =C14/$C$32 -> 0.21566555 | K14: =D14/$D$32 -> 0.13018891 | L14: =E14/$E$32 -> 0.19011728 | M14: =F14/$F$32 -> 0.34503278 | N14: =G14/$G$32 -> 0.23836565 | P14: Batatas tali, ubi, rebus | Q14: =J14*0.05 -> 0.010783277 | R14: =K14*0.25 -> 0.032547228 | S14: =L14*0.2 -> 0.038023455 | T14: =M14*0.1 -> 0.034503278 | U14: =N14*0.4 -> 0.095346259 | W14: Batatas tali, ubi, rebus | X14: =SQRT(SUMPRODUCT((Q14:U14 - Q$31:U$31)^2)) -> 0.082618102 | Y14: =SQRT(SUMPRODUCT((Q14:U14 - Q$32:U$32)^2)) -> 0.072034056 | AA14: Batatas tali, ubi, rebus | AB14: =Y14 / (X14 + Y14) -> 0.46578113
B15: Belitung, talas, kukus | C15: =IFS('data raw'!E16<=1, 1, 'data raw'!E16<=25, 2, 'data raw'!E16<=50, 3, 'data raw'!E16<=75, 4, TRUE, 5) -> 2 | D15: =IFS('data raw'!F16<=1, 1, 'data raw'!F16<=25, 2, 'data raw'!F16<=50, 3, 'data raw'!F16<=75, 4, TRUE, 5) -> 1 | E15: =IFS('data raw'!G16<=1, 1, 'data raw'!G16<=25, 2, 'data raw'!G16<=50, 3, 'data raw'!G16<=75, 4, TRUE, 5) -> 3 | F15: =IFS('data raw'!H16<=1, 1, 'data raw'!H16<=3, 2, 'data raw'!H16<=5, 3, 'data raw'!H16<=7, 4, TRUE, 5) -> 1 | G15: =IFS('data raw'!M16<=100, 5, 'data raw'!M16<=200, 4, 'data raw'!M16<=350, 3, 'data raw'!M16<=500, 2, TRUE, 1) -> 5 | I15: Belitung, talas, kukus | J15: =C15/$C$32 -> 0.21566555 | K15: =D15/$D$32 -> 0.13018891 | L15: =E15/$E$32 -> 0.19011728 | M15: =F15/$F$32 -> 0.069006556 | N15: =G15/$G$32 -> 0.23836565 | P15: Belitung, talas, kukus | Q15: =J15*0.05 -> 0.010783277 | R15: =K15*0.25 -> 0.032547228 | S15: =L15*0.2 -> 0.038023455 | T15: =M15*0.1 -> 0.0069006556 | U15: =N15*0.4 -> 0.095346259 | W15: Belitung, talas, kukus | X15: =SQRT(SUMPRODUCT((Q15:U15 - Q$31:U$31)^2)) -> 0.081091515 | Y15: =SQRT(SUMPRODUCT((Q15:U15 - Q$32:U$32)^2)) -> 0.066535708 | AA15: Belitung, talas, kukus | AB15: =Y15 / (X15 + Y15) -> 0.4507008
B16: Ketela pohon/singkong kukus | C16: =IFS('data raw'!E17<=1, 1, 'data raw'!E17<=25, 2, 'data raw'!E17<=50, 3, 'data raw'!E17<=75, 4, TRUE, 5) -> 2 | D16: =IFS('data raw'!F17<=1, 1, 'data raw'!F17<=25, 2, 'data raw'!F17<=50, 3, 'data raw'!F17<=75, 4, TRUE, 5) -> 1 | E16: =IFS('data raw'!G17<=1, 1, 'data raw'!G17<=25, 2, 'data raw'!G17<=50, 3, 'data raw'!G17<=75, 4, TRUE, 5) -> 3 | F16: =IFS('data raw'!H17<=1, 1, 'data raw'!H17<=3, 2, 'data raw'!H17<=5, 3, 'data raw'!H17<=7, 4, TRUE, 5) -> 2 | G16: =IFS('data raw'!M17<=100, 5, 'data raw'!M17<=200, 4, 'data raw'!M17<=350, 3, 'data raw'!M17<=500, 2, TRUE, 1) -> 5 | I16: Ketela pohon/singkong kukus | J16: =C16/$C$32 -> 0.21566555 | K16: =D16/$D$32 -> 0.13018891 | L16: =E16/$E$32 -> 0.19011728 | M16: =F16/$F$32 -> 0.13801311 | N16: =G16/$G$32 -> 0.23836565 | P16: Ketela pohon/singkong kukus | Q16: =J16*0.05 -> 0.010783277 | R16: =K16*0.25 -> 0.032547228 | S16: =L16*0.2 -> 0.038023455 | T16: =M16*0.1 -> 0.013801311 | U16: =N16*0.4 -> 0.095346259 | W16: Ketela pohon/singkong kukus | X16: =SQRT(SUMPRODUCT((Q16:U16 - Q$31:U$31)^2)) -> 0.080594391 | Y16: =SQRT(SUMPRODUCT((Q16:U16 - Q$32:U$32)^2)) -> 0.066892597 | AA16: Ketela pohon/singkong kukus | AB16: =Y16 / (X16 + Y16) -> 0.45354914
B17: Ubi jalar, kuning, kukus | C17: =IFS('data raw'!E18<=1, 1, 'data raw'!E18<=25, 2, 'data raw'!E18<=50, 3, 'data raw'!E18<=75, 4, TRUE, 5) -> 1 | D17: =IFS('data raw'!F18<=1, 1, 'data raw'!F18<=25, 2, 'data raw'!F18<=50, 3, 'data raw'!F18<=75, 4, TRUE, 5) -> 1 | E17: =IFS('data raw'!G18<=1, 1, 'data raw'!G18<=25, 2, 'data raw'!G18<=50, 3, 'data raw'!G18<=75, 4, TRUE, 5) -> 2 | F17: =IFS('data raw'!H18<=1, 1, 'data raw'!H18<=3, 2, 'data raw'!H18<=5, 3, 'data raw'!H18<=7, 4, TRUE, 5) -> 1 | G17: =IFS('data raw'!M18<=100, 5, 'data raw'!M18<=200, 4, 'data raw'!M18<=350, 3, 'data raw'!M18<=500, 2, TRUE, 1) -> 5 | I17: Ubi jalar, kuning, kukus | J17: =C17/$C$32 -> 0.10783277 | K17: =D17/$D$32 -> 0.13018891 | L17: =E17/$E$32 -> 0.12674485 | M17: =F17/$F$32 -> 0.069006556 | N17: =G17/$G$32 -> 0.23836565 | P17: Ubi jalar, kuning, kukus | Q17: =J17*0.05 -> 0.0053916387 | R17: =K17*0.25 -> 0.032547228 | S17: =L17*0.2 -> 0.02534897 | T17: =M17*0.1 -> 0.0069006556 | U17: =N17*0.4 -> 0.095346259 | W17: Ubi jalar, kuning, kukus | X17: =SQRT(SUMPRODUCT((Q17:U17 - Q$31:U$31)^2)) -> 0.086407499 | Y17: =SQRT(SUMPRODUCT((Q17:U17 - Q$32:U$32)^2)) -> 0.065094455 | AA17: Ubi jalar, kuning, kukus | AB17: =Y17 / (X17 + Y17) -> 0.42966083
B18: Ubi jalar tinta/ kemayung kukus | C18: =IFS('data raw'!E19<=1, 1, 'data raw'!E19<=25, 2, 'data raw'!E19<=50, 3, 'data raw'!E19<=75, 4, TRUE, 5) -> 1 | D18: =IFS('data raw'!F19<=1, 1, 'data raw'!F19<=25, 2, 'data raw'!F19<=50, 3, 'data raw'!F19<=75, 4, TRUE, 5) -> 1 | E18: =IFS('data raw'!G19<=1, 1, 'data raw'!G19<=25, 2, 'data raw'!G19<=50, 3, 'data raw'!G19<=75, 4, TRUE, 5) -> 3 | F18: =IFS('data raw'!H19<=1, 1, 'data raw'!H19<=3, 2, 'data raw'!H19<=5, 3, 'data raw'!H19<=7, 4, TRUE, 5) -> 2 | G18: =IFS('data raw'!M19<=100, 5, 'data raw'!M19<=200, 4, 'data raw'!M19<=350, 3, 'data raw'!M19<=500, 2, TRUE, 1) -> 5 | I18: Ubi jalar tinta/ kemayung kukus | J18: =C18/$C$32 -> 0.10783277 | K18: =D18/$D$32 -> 0.13018891 | L18: =E18/$E$32 -> 0.19011728 | M18: =F18/$F$32 -> 0.13801311 | N18: =G18/$G$32 -> 0.23836565 | P18: Ubi jalar tinta/ kemayung kukus | Q18: =J18*0.05 -> 0.0053916387 | R18: =K18*0.25 -> 0.032547228 | S18: =L18*0.2 -> 0.038023455 | T18: =M18*0.1 -> 0.013801311 | U18: =N18*0.4 -> 0.095346259 | W18: Ubi jalar tinta/ kemayung kukus | X18: =SQRT(SUMPRODUCT((Q18:U18 - Q$31:U$31)^2)) -> 0.081133625 | Y18: =SQRT(SUMPRODUCT((Q18:U18 - Q$32:U$32)^2)) -> 0.066674956 | AA18: Ubi jalar tinta/ kemayung kukus | AB18: =Y18 / (X18 + Y18) -> 0.45108989
B19: Ubi jalar merah, segar | C19: =IFS('data raw'!E20<=1, 1, 'data raw'!E20<=25, 2, 'data raw'!E20<=50, 3, 'data raw'!E20<=75, 4, TRUE, 5) -> 2 | D19: =IFS('data raw'!F20<=1, 1, 'data raw'!F20<=25, 2, 'data raw'!F20<=50, 3, 'data raw'!F20<=75, 4, TRUE, 5) -> 1 | E19: =IFS('data raw'!G20<=1, 1, 'data raw'!G20<=25, 2, 'data raw'!G20<=50, 3, 'data raw'!G20<=75, 4, TRUE, 5) -> 3 | F19: =IFS('data raw'!H20<=1, 1, 'data raw'!H20<=3, 2, 'data raw'!H20<=5, 3, 'data raw'!H20<=7, 4, TRUE, 5) -> 1 | G19: =IFS('data raw'!M20<=100, 5, 'data raw'!M20<=200, 4, 'data raw'!M20<=350, 3, 'data raw'!M20<=500, 2, TRUE, 1) -> 5 | I19: Ubi jalar merah, segar | J19: =C19/$C$32 -> 0.21566555 | K19: =D19/$D$32 -> 0.13018891 | L19: =E19/$E$32 -> 0.19011728 | M19: =F19/$F$32 -> 0.069006556 | N19: =G19/$G$32 -> 0.23836565 | P19: Ubi jalar merah, segar | Q19: =J19*0.05 -> 0.010783277 | R19: =K19*0.25 -> 0.032547228 | S19: =L19*0.2 -> 0.038023455 | T19: =M19*0.1 -> 0.0069006556 | U19: =N19*0.4 -> 0.095346259 | W19: Ubi jalar merah, segar | X19: =SQRT(SUMPRODUCT((Q19:U19 - Q$31:U$31)^2)) -> 0.081091515 | Y19: =SQRT(SUMPRODUCT((Q19:U19 - Q$32:U$32)^2)) -> 0.066535708 | AA19: Ubi jalar merah, segar | AB19: =Y19 / (X19 + Y19) -> 0.4507008
B20: Ubi jalar putih, segar | C20: =IFS('data raw'!E21<=1, 1, 'data raw'!E21<=25, 2, 'data raw'!E21<=50, 3, 'data raw'!E21<=75, 4, TRUE, 5) -> 1 | D20: =IFS('data raw'!F21<=1, 1, 'data raw'!F21<=25, 2, 'data raw'!F21<=50, 3, 'data raw'!F21<=75, 4, TRUE, 5) -> 1 | E20: =IFS('data raw'!G21<=1, 1, 'data raw'!G21<=25, 2, 'data raw'!G21<=50, 3, 'data raw'!G21<=75, 4, TRUE, 5) -> 2 | F20: =IFS('data raw'!H21<=1, 1, 'data raw'!H21<=3, 2, 'data raw'!H21<=5, 3, 'data raw'!H21<=7, 4, TRUE, 5) -> 3 | G20: =IFS('data raw'!M21<=100, 5, 'data raw'!M21<=200, 4, 'data raw'!M21<=350, 3, 'data raw'!M21<=500, 2, TRUE, 1) -> 5 | I20: Ubi jalar putih, segar | J20: =C20/$C$32 -> 0.10783277 | K20: =D20/$D$32 -> 0.13018891 | L20: =E20/$E$32 -> 0.12674485 | M20: =F20/$F$32 -> 0.20701967 | N20: =G20/$G$32 -> 0.23836565 | P20: Ubi jalar putih, segar | Q20: =J20*0.05 -> 0.0053916387 | R20: =K20*0.25 -> 0.032547228 | S20: =L20*0.2 -> 0.02534897 | T20: =M20*0.1 -> 0.020701967 | U20: =N20*0.4 -> 0.095346259 | W20: Ubi jalar putih, segar | X20: =SQRT(SUMPRODUCT((Q20:U20 - Q$31:U$31)^2)) -> 0.086027543 | Y20: =SQRT(SUMPRODUCT((Q20:U20 - Q$32:U$32)^2)) -> 0.066541448 | AA20: Ubi jalar putih, segar | AB20: =Y20 / (X20 + Y20) -> 0.43614005
B21: Keripik kentang | C21: =IFS('data raw'!E22<=1, 1, 'data raw'!E22<=25, 2, 'data raw'!E22<=50, 3, 'data raw'!E22<=75, 4, TRUE, 5) -> 2 | D21: =IFS('data raw'!F22<=1, 1, 'data raw'!F22<=25, 2, 'data raw'!F22<=50, 3, 'data raw'!F22<=75, 4, TRUE, 5) -> 2 | E21: =IFS('data raw'!G22<=1, 1, 'data raw'!G22<=25, 2, 'data raw'!G22<=50, 3, 'data raw'!G22<=75, 4, TRUE, 5) -> 4 | F21: =IFS('data raw'!H22<=1, 1, 'data raw'!H22<=3, 2, 'data raw'!H22<=5, 3, 'data raw'!H22<=7, 4, TRUE, 5) -> 3 | G21: =IFS('data raw'!M22<=100, 5, 'data raw'!M22<=200, 4, 'data raw'!M22<=350, 3, 'data raw'!M22<=500, 2, TRUE, 1) -> 1 | I21: Keripik kentang | J21: =C21/$C$32 -> 0.21566555 | K21: =D21/$D$32 -> 0.26037782 | L21: =E21/$E$32 -> 0.2534897 | M21: =F21/$F$32 -> 0.20701967 | N21: =G21/$G$32 -> 0.047673129 | P21: Keripik kentang | Q21: =J21*0.05 -> 0.010783277 | R21: =K21*0.25 -> 0.065094455 | S21: =L21*0.2 -> 0.05069794 | T21: =M21*0.1 -> 0.020701967 | U21: =N21*0.4 -> 0.019069252 | W21: Keripik kentang | X21: =SQRT(SUMPRODUCT((Q21:U21 - Q$31:U$31)^2)) -> 0.035630444 | Y21: =SQRT(SUMPRODUCT((Q21:U21 - Q$32:U$32)^2)) -> 0.087975111 | AA21: Keripik kentang | AB21: =Y21 / (X21 + Y21) -> 0.71174075
B22: Keripik ubi | C22: =IFS('data raw'!E23<=1, 1, 'data raw'!E23<=25, 2, 'data raw'!E23<=50, 3, 'data raw'!E23<=75, 4, TRUE, 5) -> 1 | D22: =IFS('data raw'!F23<=1, 1, 'data raw'!F23<=25, 2, 'data raw'!F23<=50, 3, 'data raw'!F23<=75, 4, TRUE, 5) -> 2 | E22: =IFS('data raw'!G23<=1, 1, 'data raw'!G23<=25, 2, 'data raw'!G23<=50, 3, 'data raw'!G23<=75, 4, TRUE, 5) -> 4 | F22: =IFS('data raw'!H23<=1, 1, 'data raw'!H23<=3, 2, 'data raw'!H23<=5, 3, 'data raw'!H23<=7, 4, TRUE, 5) -> 5 | G22: =IFS('data raw'!M23<=100, 5, 'data raw'!M23<=200, 4, 'data raw'!M23<=350, 3, 'data raw'!M23<=500, 2, TRUE, 1) -> 5 | I22: Keripik ubi | J22: =C22/$C$32 -> 0.10783277 | K22: =D22/$D$32 -> 0.26037782 | L22: =E22/$E$32 -> 0.2534897 | M22: =F22/$F$32 -> 0.34503278 | N22: =G22/$G$32 -> 0.23836565 | P22: Keripik ubi | Q22: =J22*0.05 -> 0.0053916387 | R22: =K22*0.25 -> 0.065094455 | S22: =L22*0.2 -> 0.05069794 | T22: =M22*0.1 -> 0.034503278 | U22: =N22*0.4 -> 0.095346259 | W22: Keripik ubi | X22: =SQRT(SUMPRODUCT((Q22:U22 - Q$31:U$31)^2)) -> 0.086546833 | Y22: =SQRT(SUMPRODUCT((Q22:U22 - Q$32:U$32)^2)) -> 0.049636651 | AA22: Keripik ubi | AB22: =Y22 / (X22 + Y22) -> 0.36448363
